import {
  ConflictException,
  Injectable,
  InternalServerErrorException,
} from '@nestjs/common';
import { DataSource, Repository } from 'typeorm';
import { User } from './user.entity';
import { AuthCredentialsDto } from './dto/auth-credentials.dto';
import * as bcrypt from 'bcryptjs';

@Injectable()
export class UserRepository extends Repository<User> {
  constructor(dataSource: DataSource) {
    super(User, dataSource.createEntityManager());
  }

  async createUser(authCredentialDto: AuthCredentialsDto): Promise<void> {
    const { username, password } = authCredentialDto;

    const salt = await bcrypt.genSalt();
    const hashedPassword = await bcrypt.hash(password, salt);

    const user = this.create({ username, password: hashedPassword });

    // NestJS에서 에러가 발생하면 의미없는 메시지를 내보내는 에러를 던지기 때문에 이를 잡기 위해 try ~ catch 문을 사용한다.
    try {
      await this.save(user);
    } catch (error) {
      if (error.code === '23505') {
        throw new ConflictException('Existing username');
      } else {
        throw new InternalServerErrorException();
      }
    }
  }
}
